<?xml version="1.0" encoding="utf-8"?>
<!-- =================================================================================== -->
<!-- |    This document was autogenerated by xacro from robot.xacro                    | -->
<!-- |    EDITING THIS FILE BY HAND IS NOT RECOMMENDED                                 | -->
<!-- =================================================================================== -->
<robot name="Golden_Robot">
  <!-- ~~~~~~~~~~~~~~~~~~~~~~~~~~~~~~~~~~~~~~ XACROS END ~~~~~~~~~~~~~~~~~~~~~~~~~~~~~~~~~~~~~~ -->
  <material name="gold">
    <color rgba="0.992 0.788 0.04 1"/>
  </material>
  <material name="black">
    <color rgba="0 0 0 1"/>
  </material>
  <!-- ~~~~~~~~~~~~~~~~~~~~~~~~~~~~~~~~~~~~~~ LINKS BEGIN ~~~~~~~~~~~~~~~~~~~~~~~~~~~~~~~~~~~~~~ -->
  <link name="link 0">
    <visual>
      <geometry>
        <cylinder length="0.25" radius="1.5"/>
      </geometry>
      <origin rpy="0 0 0" xyz="0 0 0"/>
      <material name="gold"/>
    </visual>
    <collision>
      <geometry>
        <cylinder length="0.25" radius="1.5"/>
      </geometry>
      <origin rpy="0 0 0" xyz="0 0 0"/>
    </collision>
    <inertial>
      <mass value="1"/>
      <inertia ixx="1" ixy="0" ixz="0" iyy="1" iyz="0" izz="1"/>
    </inertial>
  </link>
  <link name="link 1">
    <visual>
      <geometry>
        <cylinder length="0.5" radius="1"/>
      </geometry>
      <origin rpy="0 0 0" xyz="0 0 0.25"/>
      <material name="black"/>
    </visual>
    <collision>
      <geometry>
        <cylinder length="0.5" radius="1"/>
      </geometry>
      <origin rpy="0 0 0" xyz="0 0 0.25"/>
    </collision>
    <inertial>
      <mass value="1"/>
      <inertia ixx="1" ixy="0" ixz="0" iyy="1" iyz="0" izz="1"/>
    </inertial>
  </link>
  <link name="link 2">
    <visual>
      <geometry>
        <cylinder length="3.5" radius="0.25"/>
      </geometry>
      <origin rpy="0 0 0" xyz="0 0 1.75"/>
      <material name="gold"/>
    </visual>
    <visual>
      <geometry>
        <box size="0.75 0.15 0.2"/>
      </geometry>
      <origin rpy="0 0 0" xyz="-0.375 0.175 3.4"/>
      <material name="gold"/>
    </visual>
    <visual>
      <geometry>
        <box size="0.75 0.15 0.2"/>
      </geometry>
      <origin rpy="0 0 0" xyz="-0.375 -0.175 3.4"/>
      <material name="gold"/>
    </visual>
    <visual>
      <geometry>
        <sphere radius="0.25"/>
      </geometry>
      <origin rpy="0 0 0" xyz="0 0 3.5"/>
      <material name="gold"/>
    </visual>
    <!-- collision begin -->
    <collision>
      <geometry>
        <cylinder length="3.5" radius="0.25"/>
      </geometry>
      <origin rpy="0 0 0" xyz="0 0 1.75"/>
    </collision>
    <collision>
      <geometry>
        <box size="0.75 0.15 0.2"/>
      </geometry>
      <origin rpy="0 0 0" xyz="-0.375 0.175 3.4"/>
    </collision>
    <collision>
      <geometry>
        <box size="0.75 0.15 0.2"/>
      </geometry>
      <origin rpy="0 0 0" xyz="-0.375 -0.175 3.4"/>
    </collision>
    <collision>
      <geometry>
        <sphere radius="0.25"/>
      </geometry>
      <origin rpy="0 0 0" xyz="0 0 3.5"/>
    </collision>
    <!-- collision end -->
    <inertial>
      <mass value="1"/>
      <inertia ixx="1" ixy="0" ixz="0" iyy="1" iyz="0" izz="1"/>
    </inertial>
  </link>
  <link name="link 3">
    <visual>
      <geometry>
        <box size="2 0.2 0.2"/>
      </geometry>
      <origin rpy="0 0 0" xyz="-1.0 0 0"/>
      <material name="black"/>
    </visual>
    <collision>
      <geometry>
        <box size="2 0.2 0.2"/>
      </geometry>
      <origin rpy="0 0 0" xyz="-1.0 0 0"/>
    </collision>
    <inertial>
      <mass value="1"/>
      <inertia ixx="1" ixy="0" ixz="0" iyy="1" iyz="0" izz="1"/>
    </inertial>
  </link>
  <link name="link 4">
    <visual>
      <geometry>
        <box size="1.5 0.05 0.2"/>
      </geometry>
      <origin rpy="0 0 0" xyz="-0.75 0.125 0"/>
      <material name="gold"/>
    </visual>
    <visual>
      <geometry>
        <box size="1.5 0.05 0.2"/>
      </geometry>
      <origin rpy="0 0 0" xyz="-0.75 -0.125 0"/>
      <material name="gold"/>
    </visual>
    <!-- collision begin -->
    <collision>
      <geometry>
        <box size="1.5 0.05 0.2"/>
      </geometry>
      <origin rpy="0 0 0" xyz="-0.75 0.125 0"/>
    </collision>
    <collision>
      <geometry>
        <box size="1.5 0.05 0.2"/>
      </geometry>
      <origin rpy="0 0 0" xyz="-0.75 -0.125 0"/>
    </collision>
    <!-- collision end -->
    <inertial>
      <mass value="1"/>
      <inertia ixx="1" ixy="0" ixz="0" iyy="1" iyz="0" izz="1"/>
    </inertial>
  </link>
  <link name="link 5">
    <visual>
      <geometry>
        <box size="0.75 0.2 0.2"/>
      </geometry>
      <origin rpy="0 0 0" xyz="-0.375 0 0"/>
      <material name="black"/>
    </visual>
    <collision>
      <geometry>
        <box size="0.75 0.2 0.2"/>
      </geometry>
      <origin rpy="0 0 0" xyz="-0.375 0 0"/>
    </collision>
    <inertial>
      <mass value="1"/>
      <inertia ixx="1" ixy="0" ixz="0" iyy="1" iyz="0" izz="1"/>
    </inertial>
  </link>
  <!-- LINKS END -->
  <!-- ~~~~~~~~~~~~~~~~~~~~~~~~~~~~~~~~~~~~~~ JOINTS BEGIN ~~~~~~~~~~~~~~~~~~~~~~~~~~~~~~~~~~~~~~ -->
  <joint name="links-0-1" type="continuous">
    <parent link="link 0"/>
    <child link="link 1"/>
    <origin xyz="0 0 0.125"/>
    <axis xyz="0 0 1"/>
  </joint>
  <joint name="links-1-2" type="fixed">
    <parent link="link 1"/>
    <child link="link 2"/>
    <origin xyz="0 0 0.5"/>
  </joint>
  <joint name="links-2-3" type="revolute">
    <parent link="link 2"/>
    <child link="link 3"/>
    <origin xyz="-0.55 0 3.4"/>
    <axis xyz="0 1 0"/>
    <limit effort="10" lower="-1.5707963268" upper="1.5707963268" velocity="3"/>
  </joint>
  <joint name="links-3-4" type="continuous">
    <parent link="link 3"/>
    <child link="link 4"/>
    <origin xyz="-1.8 0 0"/>
    <axis xyz="0 1 0"/>
  </joint>
  <joint name="links-4-5" type="continuous">
    <parent link="link 4"/>
    <child link="link 5"/>
    <origin xyz="-1.4 0 0"/>
    <axis xyz="0 1 0"/>
  </joint>
  <!-- ~~~~~~~~~~~~~~~~~~~~~~~~~~~~~~~~~~~~~~ JOINTS END ~~~~~~~~~~~~~~~~~~~~~~~~~~~~~~~~~~~~~~ -->
</robot>

